Workbook

Sheet Start Here
A1: ABC Tutoring — Analytics Report
A2: A customer-friendly workbook for website interest, tutor demand, and booking conversion.
A4: IMPORTANT DATA NOTE
A5: The Event Data sheet currently contains 25 clearly labeled illustrative synthetic visitors so the report is useful immediately. It is not real customer activity. Replace those rows with a PostHog CSV export before reporting real performance.
A8: Step | B8: Action | C8: What to do
A9: 1 | B9: Open the report | C9: Use KPI Summary for the high-level story and the detail sheets for tutor, subject, funnel, and source performance.
A10: 2 | B10: Export PostHog data | C10: In PostHog, export the tracked events for the reporting period as CSV.
A11: 3 | B11: Paste into Event Data | C11: Keep the same column order. Never add parent email, student name, or other personal information.
A12: 4 | B12: Separate demo traffic | C12: Use Synthetic traffic = TRUE for demonstrations and FALSE for real reporting.
A13: 5 | B13: Share safely | C13: Share KPI and detail tabs with Dana. Retain the data-status note and date range so the numbers cannot be mistaken for live results.
A15: Sharing rule | B15: Recommendation
A16: Customer dashboard | B16: Filter Synthetic traffic to FALSE.
A17: Demo dashboard | B17: Filter Synthetic traffic to TRUE.
A18: One simulation | B18: Filter Simulation run ID to the ID printed by the simulator.
A19: Privacy | B19: No parent or student personally identifiable information is captured in this workbook.

Sheet Event Data
A1: Event time | B1: Event name | C1: Visitor/session ID | D1: Tutor ID | E1: Tutor name | F1: Subject | G1: Session format | H1: Booking stage | I1: Traffic source | J1: Synthetic traffic | K1: Simulation run ID | L1: Data status
A2: 46268.5 | B2: simulation_session_started | C2: demo-visitor-01 | I2: direct | J2: TRUE | K2: illustrative_demo_25 | L2: Illustrative sample—not a PostHog export
A3: 46268.5 | B3: $pageview | C3: demo-visitor-01 | I3: direct | J3: TRUE | K3: illustrative_demo_25 | L3: Illustrative sample—not a PostHog export
A4: 46268.501 | B4: simulation_session_started | C4: demo-visitor-02 | I4: google | J4: TRUE | K4: illustrative_demo_25 | L4: Illustrative sample—not a PostHog export
A5: 46268.501 | B5: $pageview | C5: demo-visitor-02 | I5: google | J5: TRUE | K5: illustrative_demo_25 | L5: Illustrative sample—not a PostHog export
A6: 46268.501 | B6: tutor_list_filtered | C6: demo-visitor-02 | D6: marcus-reed | E6: Marcus Reed | F6: Math | G6: In person | I6: google | J6: TRUE | K6: illustrative_demo_25 | L6: Illustrative sample—not a PostHog export
A7: 46268.501 | B7: subject_interest | C7: demo-visitor-02 | D7: marcus-reed | E7: Marcus Reed | F7: Math | G7: In person | I7: google | J7: TRUE | K7: illustrative_demo_25 | L7: Illustrative sample—not a PostHog export
A8: 46268.501 | B8: tutor_profile_viewed | C8: demo-visitor-02 | D8: marcus-reed | E8: Marcus Reed | F8: Math | G8: In person | I8: google | J8: TRUE | K8: illustrative_demo_25 | L8: Illustrative sample—not a PostHog export
A9: 46268.501 | B9: simulation_session_started | C9: demo-visitor-03 | I9: facebook | J9: TRUE | K9: illustrative_demo_25 | L9: Illustrative sample—not a PostHog export
A10: 46268.501 | B10: $pageview | C10: demo-visitor-03 | I10: facebook | J10: TRUE | K10: illustrative_demo_25 | L10: Illustrative sample—not a PostHog export
A11: 46268.501 | B11: tutor_list_filtered | C11: demo-visitor-03 | D11: maya-chen | E11: Maya Chen | F11: Math | G11: Online | I11: facebook | J11: TRUE | K11: illustrative_demo_25 | L11: Illustrative sample—not a PostHog export
A12: 46268.502 | B12: subject_interest | C12: demo-visitor-03 | D12: maya-chen | E12: Maya Chen | F12: Math | G12: Online | I12: facebook | J12: TRUE | K12: illustrative_demo_25 | L12: Illustrative sample—not a PostHog export
A13: 46268.502 | B13: tutor_profile_viewed | C13: demo-visitor-03 | D13: maya-chen | E13: Maya Chen | F13: Math | G13: Online | I13: facebook | J13: TRUE | K13: illustrative_demo_25 | L13: Illustrative sample—not a PostHog export
A14: 46268.502 | B14: simulation_session_started | C14: demo-visitor-04 | I14: newsletter | J14: TRUE | K14: illustrative_demo_25 | L14: Illustrative sample—not a PostHog export
A15: 46268.502 | B15: $pageview | C15: demo-visitor-04 | I15: newsletter | J15: TRUE | K15: illustrative_demo_25 | L15: Illustrative sample—not a PostHog export
A16: 46268.502 | B16: tutor_list_filtered | C16: demo-visitor-04 | D16: arjun-patel | E16: Arjun Patel | F16: Science | G16: In person | I16: newsletter | J16: TRUE | K16: illustrative_demo_25 | L16: Illustrative sample—not a PostHog export
A17: 46268.502 | B17: subject_interest | C17: demo-visitor-04 | D17: arjun-patel | E17: Arjun Patel | F17: Science | G17: In person | I17: newsletter | J17: TRUE | K17: illustrative_demo_25 | L17: Illustrative sample—not a PostHog export
A18: 46268.502 | B18: tutor_availability_viewed | C18: demo-visitor-04 | D18: arjun-patel | E18: Arjun Patel | F18: Science | G18: In person | H18: availability | I18: newsletter | J18: TRUE | K18: illustrative_demo_25 | L18: Illustrative sample—not a PostHog export
A19: 46268.502 | B19: booking_abandoned | C19: demo-visitor-04 | D19: arjun-patel | E19: Arjun Patel | F19: Science | G19: In person | H19: availability | I19: newsletter | J19: TRUE | K19: illustrative_demo_25 | L19: Illustrative sample—not a PostHog export
A20: 46268.503 | B20: simulation_session_started | C20: demo-visitor-05 | I20: direct | J20: TRUE | K20: illustrative_demo_25 | L20: Illustrative sample—not a PostHog export
A21: 46268.503 | B21: $pageview | C21: demo-visitor-05 | I21: direct | J21: TRUE | K21: illustrative_demo_25 | L21: Illustrative sample—not a PostHog export
A22: 46268.503 | B22: tutor_list_filtered | C22: demo-visitor-05 | D22: claire-bennett | E22: Claire Bennett | F22: Reading | G22: Online | I22: direct | J22: TRUE | K22: illustrative_demo_25 | L22: Illustrative sample—not a PostHog export
A23: 46268.503 | B23: subject_interest | C23: demo-visitor-05 | D23: claire-bennett | E23: Claire Bennett | F23: Reading | G23: Online | I23: direct | J23: TRUE | K23: illustrative_demo_25 | L23: Illustrative sample—not a PostHog export
A24: 46268.503 | B24: tutor_availability_viewed | C24: demo-visitor-05 | D24: claire-bennett | E24: Claire Bennett | F24: Reading | G24: Online | H24: availability | I24: direct | J24: TRUE | K24: illustrative_demo_25 | L24: Illustrative sample—not a PostHog export
A25: 46268.503 | B25: booking_abandoned | C25: demo-visitor-05 | D25: claire-bennett | E25: Claire Bennett | F25: Reading | G25: Online | H25: availability | I25: direct | J25: TRUE | K25: illustrative_demo_25 | L25: Illustrative sample—not a PostHog export
A26: 46268.504 | B26: simulation_session_started | C26: demo-visitor-06 | I26: google | J26: TRUE | K26: illustrative_demo_25 | L26: Illustrative sample—not a PostHog export
A27: 46268.504 | B27: $pageview | C27: demo-visitor-06 | I27: google | J27: TRUE | K27: illustrative_demo_25 | L27: Illustrative sample—not a PostHog export
A28: 46268.504 | B28: tutor_list_filtered | C28: demo-visitor-06 | D28: noah-williams | E28: Noah Williams | F28: Math | G28: In person | I28: google | J28: TRUE | K28: illustrative_demo_25 | L28: Illustrative sample—not a PostHog export
A29: 46268.504 | B29: subject_interest | C29: demo-visitor-06 | D29: noah-williams | E29: Noah Williams | F29: Math | G29: In person | I29: google | J29: TRUE | K29: illustrative_demo_25 | L29: Illustrative sample—not a PostHog export
A30: 46268.504 | B30: tutor_availability_viewed | C30: demo-visitor-06 | D30: noah-williams | E30: Noah Williams | F30: Math | G30: In person | H30: availability | I30: google | J30: TRUE | K30: illustrative_demo_25 | L30: Illustrative sample—not a PostHog export
A31: 46268.504 | B31: booking_details_viewed | C31: demo-visitor-06 | D31: noah-williams | E31: Noah Williams | F31: Math | G31: In person | H31: details | I31: google | J31: TRUE | K31: illustrative_demo_25 | L31: Illustrative sample—not a PostHog export
A32: 46268.504 | B32: booking_abandoned | C32: demo-visitor-06 | D32: noah-williams | E32: Noah Williams | F32: Math | G32: In person | H32: details | I32: google | J32: TRUE | K32: illustrative_demo_25 | L32: Illustrative sample—not a PostHog export
A33: 46268.505 | B33: simulation_session_started | C33: demo-visitor-07 | I33: facebook | J33: TRUE | K33: illustrative_demo_25 | L33: Illustrative sample—not a PostHog export
A34: 46268.505 | B34: $pageview | C34: demo-visitor-07 | I34: facebook | J34: TRUE | K34: illustrative_demo_25 | L34: Illustrative sample—not a PostHog export
A35: 46268.505 | B35: tutor_list_filtered | C35: demo-visitor-07 | D35: elena-torres | E35: Elena Torres | F35: Math | G35: Online | I35: facebook | J35: TRUE | K35: illustrative_demo_25 | L35: Illustrative sample—not a PostHog export
A36: 46268.505 | B36: subject_interest | C36: demo-visitor-07 | D36: elena-torres | E36: Elena Torres | F36: Math | G36: Online | I36: facebook | J36: TRUE | K36: illustrative_demo_25 | L36: Illustrative sample—not a PostHog export
A37: 46268.505 | B37: tutor_availability_viewed | C37: demo-visitor-07 | D37: elena-torres | E37: Elena Torres | F37: Math | G37: Online | H37: availability | I37: facebook | J37: TRUE | K37: illustrative_demo_25 | L37: Illustrative sample—not a PostHog export
A38: 46268.505 | B38: booking_details_viewed | C38: demo-visitor-07 | D38: elena-torres | E38: Elena Torres | F38: Math | G38: Online | H38: details | I38: facebook | J38: TRUE | K38: illustrative_demo_25 | L38: Illustrative sample—not a PostHog export
A39: 46268.505 | B39: booking_completed | C39: demo-visitor-07 | D39: elena-torres | E39: Elena Torres | F39: Math | G39: Online | H39: complete | I39: facebook | J39: TRUE | K39: illustrative_demo_25 | L39: Illustrative sample—not a PostHog export
A40: 46268.505 | B40: simulation_session_started | C40: demo-visitor-08 | I40: newsletter | J40: TRUE | K40: illustrative_demo_25 | L40: Illustrative sample—not a PostHog export
...

Sheet KPI Summary
A1: ABC Tutoring — KPI Summary
A2: Illustrative synthetic data is shown separately from real visitor data. Update Event Data to refresh formulas.
A4: Metric | B4: Real visitors | C4: Synthetic demo | D4: Combined | E4: Meaning
A5: Website visits | B5: =COUNTIFS('Event Data'!$B$2:$B$10000,"$pageview",'Event Data'!$J$2:$J$10000,FALSE) | C5: =COUNTIFS('Event Data'!$B$2:$B$10000,"$pageview",'Event Data'!$J$2:$J$10000,TRUE) | D5: =B5+C5 | E5: Landing-page visits
A6: Tutor profiles viewed | B6: =COUNTIFS('Event Data'!$B$2:$B$10000,"tutor_profile_viewed",'Event Data'!$J$2:$J$10000,FALSE) | C6: =COUNTIFS('Event Data'!$B$2:$B$10000,"tutor_profile_viewed",'Event Data'!$J$2:$J$10000,TRUE) | D6: =B6+C6 | E6: Direct tutor-profile interest
A7: Availability viewed | B7: =COUNTIFS('Event Data'!$B$2:$B$10000,"tutor_availability_viewed",'Event Data'!$J$2:$J$10000,FALSE) | C7: =COUNTIFS('Event Data'!$B$2:$B$10000,"tutor_availability_viewed",'Event Data'!$J$2:$J$10000,TRUE) | D7: =B7+C7 | E7: Visitors who opened a tutor's schedule
A8: Booking details reached | B8: =COUNTIFS('Event Data'!$B$2:$B$10000,"booking_details_viewed",'Event Data'!$J$2:$J$10000,FALSE) | C8: =COUNTIFS('Event Data'!$B$2:$B$10000,"booking_details_viewed",'Event Data'!$J$2:$J$10000,TRUE) | D8: =B8+C8 | E8: Visitors who progressed to the information form
A9: Bookings completed | B9: =COUNTIFS('Event Data'!$B$2:$B$10000,"booking_completed",'Event Data'!$J$2:$J$10000,FALSE) | C9: =COUNTIFS('Event Data'!$B$2:$B$10000,"booking_completed",'Event Data'!$J$2:$J$10000,TRUE) | D9: =B9+C9 | E9: Prototype booking confirmations
A10: Bookings abandoned | B10: =COUNTIFS('Event Data'!$B$2:$B$10000,"booking_abandoned",'Event Data'!$J$2:$J$10000,FALSE) | C10: =COUNTIFS('Event Data'!$B$2:$B$10000,"booking_abandoned",'Event Data'!$J$2:$J$10000,TRUE) | D10: =B10+C10 | E10: Booking flows closed before completion
A12: Visit-to-booking conversion | B12: =IFERROR(B9/B5,0) | C12: =IFERROR(C9/C5,0) | D12: =IFERROR(D9/D5,0) | E12: Completed bookings divided by website visits

Sheet Booking Funnel
A1: Booking Funnel
A2: Use the Real column for customer reporting and Synthetic for demonstrations.
A4: Step | B4: Stage | C4: PostHog event | D4: Real | E4: Synthetic | F4: Synthetic step rate
A5: 1 | B5: Website visit | C5: $pageview | D5: =COUNTIFS('Event Data'!$B$2:$B$10000,C5,'Event Data'!$J$2:$J$10000,FALSE) | E5: =COUNTIFS('Event Data'!$B$2:$B$10000,C5,'Event Data'!$J$2:$J$10000,TRUE) | F5: 1
A6: 2 | B6: Subject interest | C6: subject_interest | D6: =COUNTIFS('Event Data'!$B$2:$B$10000,C6,'Event Data'!$J$2:$J$10000,FALSE) | E6: =COUNTIFS('Event Data'!$B$2:$B$10000,C6,'Event Data'!$J$2:$J$10000,TRUE) | F6: =IFERROR(E6/E5,0)
A7: 3 | B7: Tutor profile viewed | C7: tutor_profile_viewed | D7: =COUNTIFS('Event Data'!$B$2:$B$10000,C7,'Event Data'!$J$2:$J$10000,FALSE) | E7: =COUNTIFS('Event Data'!$B$2:$B$10000,C7,'Event Data'!$J$2:$J$10000,TRUE) | F7: =IFERROR(E7/E6,0)
A8: 4 | B8: Availability viewed | C8: tutor_availability_viewed | D8: =COUNTIFS('Event Data'!$B$2:$B$10000,C8,'Event Data'!$J$2:$J$10000,FALSE) | E8: =COUNTIFS('Event Data'!$B$2:$B$10000,C8,'Event Data'!$J$2:$J$10000,TRUE) | F8: =IFERROR(E8/E7,0)
A9: 5 | B9: Booking details reached | C9: booking_details_viewed | D9: =COUNTIFS('Event Data'!$B$2:$B$10000,C9,'Event Data'!$J$2:$J$10000,FALSE) | E9: =COUNTIFS('Event Data'!$B$2:$B$10000,C9,'Event Data'!$J$2:$J$10000,TRUE) | F9: =IFERROR(E9/E8,0)
A10: 6 | B10: Booking completed | C10: booking_completed | D10: =COUNTIFS('Event Data'!$B$2:$B$10000,C10,'Event Data'!$J$2:$J$10000,FALSE) | E10: =COUNTIFS('Event Data'!$B$2:$B$10000,C10,'Event Data'!$J$2:$J$10000,TRUE) | F10: =IFERROR(E10/E9,0)

Sheet Tutor Performance
A1: Tutor Performance
A2: Counts below use synthetic demonstration events only until real PostHog data is imported.
A4: Tutor ID | B4: Tutor | C4: Subject | D4: Profile views | E4: Availability views | F4: Bookings | G4: Booking rate
A5: elena-torres | B5: Elena Torres | C5: Math | D5: =COUNTIFS('Event Data'!$B$2:$B$10000,"tutor_profile_viewed",'Event Data'!$D$2:$D$10000,A5,'Event Data'!$J$2:$J$10000,TRUE) | E5: =COUNTIFS('Event Data'!$B$2:$B$10000,"tutor_availability_viewed",'Event Data'!$D$2:$D$10000,A5,'Event Data'!$J$2:$J$10000,TRUE) | F5: =COUNTIFS('Event Data'!$B$2:$B$10000,"booking_completed",'Event Data'!$D$2:$D$10000,A5,'Event Data'!$J$2:$J$10000,TRUE) | G5: =IFERROR(F5/(D5+E5),0)
A6: marcus-reed | B6: Marcus Reed | C6: Math | D6: =COUNTIFS('Event Data'!$B$2:$B$10000,"tutor_profile_viewed",'Event Data'!$D$2:$D$10000,A6,'Event Data'!$J$2:$J$10000,TRUE) | E6: =COUNTIFS('Event Data'!$B$2:$B$10000,"tutor_availability_viewed",'Event Data'!$D$2:$D$10000,A6,'Event Data'!$J$2:$J$10000,TRUE) | F6: =COUNTIFS('Event Data'!$B$2:$B$10000,"booking_completed",'Event Data'!$D$2:$D$10000,A6,'Event Data'!$J$2:$J$10000,TRUE) | G6: =IFERROR(F6/(D6+E6),0)
A7: maya-chen | B7: Maya Chen | C7: Math | D7: =COUNTIFS('Event Data'!$B$2:$B$10000,"tutor_profile_viewed",'Event Data'!$D$2:$D$10000,A7,'Event Data'!$J$2:$J$10000,TRUE) | E7: =COUNTIFS('Event Data'!$B$2:$B$10000,"tutor_availability_viewed",'Event Data'!$D$2:$D$10000,A7,'Event Data'!$J$2:$J$10000,TRUE) | F7: =COUNTIFS('Event Data'!$B$2:$B$10000,"booking_completed",'Event Data'!$D$2:$D$10000,A7,'Event Data'!$J$2:$J$10000,TRUE) | G7: =IFERROR(F7/(D7+E7),0)
A8: arjun-patel | B8: Arjun Patel | C8: Science | D8: =COUNTIFS('Event Data'!$B$2:$B$10000,"tutor_profile_viewed",'Event Data'!$D$2:$D$10000,A8,'Event Data'!$J$2:$J$10000,TRUE) | E8: =COUNTIFS('Event Data'!$B$2:$B$10000,"tutor_availability_viewed",'Event Data'!$D$2:$D$10000,A8,'Event Data'!$J$2:$J$10000,TRUE) | F8: =COUNTIFS('Event Data'!$B$2:$B$10000,"booking_completed",'Event Data'!$D$2:$D$10000,A8,'Event Data'!$J$2:$J$10000,TRUE) | G8: =IFERROR(F8/(D8+E8),0)
A9: claire-bennett | B9: Claire Bennett | C9: Reading | D9: =COUNTIFS('Event Data'!$B$2:$B$10000,"tutor_profile_viewed",'Event Data'!$D$2:$D$10000,A9,'Event Data'!$J$2:$J$10000,TRUE) | E9: =COUNTIFS('Event Data'!$B$2:$B$10000,"tutor_availability_viewed",'Event Data'!$D$2:$D$10000,A9,'Event Data'!$J$2:$J$10000,TRUE) | F9: =COUNTIFS('Event Data'!$B$2:$B$10000,"booking_completed",'Event Data'!$D$2:$D$10000,A9,'Event Data'!$J$2:$J$10000,TRUE) | G9: =IFERROR(F9/(D9+E9),0)
A10: noah-williams | B10: Noah Williams | C10: Math | D10: =COUNTIFS('Event Data'!$B$2:$B$10000,"tutor_profile_viewed",'Event Data'!$D$2:$D$10000,A10,'Event Data'!$J$2:$J$10000,TRUE) | E10: =COUNTIFS('Event Data'!$B$2:$B$10000,"tutor_availability_viewed",'Event Data'!$D$2:$D$10000,A10,'Event Data'!$J$2:$J$10000,TRUE) | F10: =COUNTIFS('Event Data'!$B$2:$B$10000,"booking_completed",'Event Data'!$D$2:$D$10000,A10,'Event Data'!$J$2:$J$10000,TRUE) | G10: =IFERROR(F10/(D10+E10),0)

Sheet Subject Interest
A1: Subject Interest
A2: Shows what families browse and which subjects lead to bookings.
A4: Subject | B4: Interest events | C4: Availability views | D4: Bookings | E4: Interpretation
A5: Math | B5: =COUNTIFS('Event Data'!$B$2:$B$10000,"subject_interest",'Event Data'!$F$2:$F$10000,A5,'Event Data'!$J$2:$J$10000,TRUE) | C5: =COUNTIFS('Event Data'!$B$2:$B$10000,"tutor_availability_viewed",'Event Data'!$F$2:$F$10000,A5,'Event Data'!$J$2:$J$10000,TRUE) | D5: =COUNTIFS('Event Data'!$B$2:$B$10000,"booking_completed",'Event Data'!$F$2:$F$10000,A5,'Event Data'!$J$2:$J$10000,TRUE) | E5: Compare interest with bookings to identify unmet demand.
A6: Science | B6: =COUNTIFS('Event Data'!$B$2:$B$10000,"subject_interest",'Event Data'!$F$2:$F$10000,A6,'Event Data'!$J$2:$J$10000,TRUE) | C6: =COUNTIFS('Event Data'!$B$2:$B$10000,"tutor_availability_viewed",'Event Data'!$F$2:$F$10000,A6,'Event Data'!$J$2:$J$10000,TRUE) | D6: =COUNTIFS('Event Data'!$B$2:$B$10000,"booking_completed",'Event Data'!$F$2:$F$10000,A6,'Event Data'!$J$2:$J$10000,TRUE) | E6: Compare interest with bookings to identify unmet demand.
A7: Reading | B7: =COUNTIFS('Event Data'!$B$2:$B$10000,"subject_interest",'Event Data'!$F$2:$F$10000,A7,'Event Data'!$J$2:$J$10000,TRUE) | C7: =COUNTIFS('Event Data'!$B$2:$B$10000,"tutor_availability_viewed",'Event Data'!$F$2:$F$10000,A7,'Event Data'!$J$2:$J$10000,TRUE) | D7: =COUNTIFS('Event Data'!$B$2:$B$10000,"booking_completed",'Event Data'!$F$2:$F$10000,A7,'Event Data'!$J$2:$J$10000,TRUE) | E7: Compare interest with bookings to identify unmet demand.

Sheet Traffic Sources
A1: Traffic Sources
A2: UTM source data helps Dana understand which outreach channels produce bookings.
A4: Source | B4: Visits | C4: Bookings | D4: Conversion rate | E4: Recommended use
A5: direct | B5: =COUNTIFS('Event Data'!$B$2:$B$10000,"$pageview",'Event Data'!$I$2:$I$10000,A5,'Event Data'!$J$2:$J$10000,TRUE) | C5: =COUNTIFS('Event Data'!$B$2:$B$10000,"booking_completed",'Event Data'!$I$2:$I$10000,A5,'Event Data'!$J$2:$J$10000,TRUE) | D5: =IFERROR(C5/B5,0) | E5: Compare volume and conversion before changing marketing effort.
A6: google | B6: =COUNTIFS('Event Data'!$B$2:$B$10000,"$pageview",'Event Data'!$I$2:$I$10000,A6,'Event Data'!$J$2:$J$10000,TRUE) | C6: =COUNTIFS('Event Data'!$B$2:$B$10000,"booking_completed",'Event Data'!$I$2:$I$10000,A6,'Event Data'!$J$2:$J$10000,TRUE) | D6: =IFERROR(C6/B6,0) | E6: Compare volume and conversion before changing marketing effort.
A7: facebook | B7: =COUNTIFS('Event Data'!$B$2:$B$10000,"$pageview",'Event Data'!$I$2:$I$10000,A7,'Event Data'!$J$2:$J$10000,TRUE) | C7: =COUNTIFS('Event Data'!$B$2:$B$10000,"booking_completed",'Event Data'!$I$2:$I$10000,A7,'Event Data'!$J$2:$J$10000,TRUE) | D7: =IFERROR(C7/B7,0) | E7: Compare volume and conversion before changing marketing effort.
A8: newsletter | B8: =COUNTIFS('Event Data'!$B$2:$B$10000,"$pageview",'Event Data'!$I$2:$I$10000,A8,'Event Data'!$J$2:$J$10000,TRUE) | C8: =COUNTIFS('Event Data'!$B$2:$B$10000,"booking_completed",'Event Data'!$I$2:$I$10000,A8,'Event Data'!$J$2:$J$10000,TRUE) | D8: =IFERROR(C8/B8,0) | E8: Compare volume and conversion before changing marketing effort.

Sheet Data Dictionary
A1: PostHog Data Dictionary
A2: Definitions make the workbook understandable when shared outside the development team.
A4: Event/property | B4: Type | C4: Definition | D4: Used for
A5: $pageview | B5: Event | C5: A visit to the ABC Tutoring page. | D5: Traffic and conversion denominator
A6: subject_interest | B6: Event | C6: A visitor selected a subject card. | D6: Subject demand
A7: tutor_profile_viewed | B7: Event | C7: A visitor opened more information about a tutor. | D7: Tutor popularity
A8: tutor_availability_viewed | B8: Event | C8: A visitor opened the tutor's scheduling flow. | D8: High-intent tutor interest
A9: booking_details_viewed | B9: Event | C9: A visitor continued from time selection to booking details. | D9: Funnel progression
A10: booking_completed | B10: Event | C10: The prototype showed a booking confirmation. | D10: Booking conversion
A11: booking_abandoned | B11: Event | C11: The booking modal closed before completion. | D11: Funnel abandonment
A12: contact_clicked | B12: Event | C12: A phone or email contact link was selected. | D12: Direct contact interest
A13: tutor_id / tutor_name | B13: Property | C13: Stable tutor identifier and readable tutor name. | D13: Tutor breakdown
A14: subject | B14: Property | C14: Math, Science, or Reading. | D14: Subject breakdown
A15: session_format | B15: Property | C15: Online or in person. | D15: Service-format demand
... A18: Traffic source | B18: Property | C18: UTM source or direct traffic. | D18: Marketing attribution

Sheet Tutor Directory
A1: Tutor Directory
A2: Reference data used to interpret tutor IDs in PostHog exports.
A4: Tutor ID | B4: Tutor | C4: Subject | D4: Grade levels | E4: Hourly rate
A5: elena-torres | B5: Elena Torres | C5: Math | D5: Grades 3-8 | E5: 45
A6: marcus-reed | B6: Marcus Reed | C6: Math | D6: Grades 6-12 | E6: 52
A7: maya-chen | B7: Maya Chen | C7: Math | D7: Grades 6-12 | E7: 55
A8: arjun-patel | B8: Arjun Patel | C8: Science | D8: Grades 6-12 | E8: 50
A9: claire-bennett | B9: Claire Bennett | C9: Reading | D9: Grades K-6 | E9: 40
A10: noah-williams | B10: Noah Williams | C10: Math | D10: Grades K-5 | E10: 42
